2020-04-19 00:50:58,181 INFO: Saccostartup [in D:\Apis\Flaskprojects\SaccoPaymentGateway\gateway\__init__.py:61]
2020-04-19 00:55:41,848 INFO: Saccostartup [in D:\Apis\Flaskprojects\SaccoPaymentGateway\gateway\__init__.py:61]
2020-04-19 00:56:25,805 INFO: Saccostartup [in D:\Apis\Flaskprojects\SaccoPaymentGateway\gateway\__init__.py:61]
2020-04-19 01:08:22,887 INFO: Saccostartup [in D:\Apis\Flaskprojects\SaccoPaymentGateway\gateway\__init__.py:61]
2020-04-19 01:18:54,890 INFO: Saccostartup [in D:\Apis\Flaskprojects\SaccoPaymentGateway\gateway\__init__.py:61]
2020-04-19 01:32:24,204 ERROR: Exception on /api/ApplyLoan [POST] [in D:\Apis\Flaskprojects\SaccoPaymentGateway\venv\lib\site-packages\flask\app.py:1891]
Traceback (most recent call last):
  File "D:\Apis\Flaskprojects\SaccoPaymentGateway\venv\lib\site-packages\flask\app.py", line 2446, in wsgi_app
    response = self.full_dispatch_request()
  File "D:\Apis\Flaskprojects\SaccoPaymentGateway\venv\lib\site-packages\flask\app.py", line 1951, in full_dispatch_request
    rv = self.handle_user_exception(e)
  File "D:\Apis\Flaskprojects\SaccoPaymentGateway\venv\lib\site-packages\flask_cors\extension.py", line 161, in wrapped_function
    return cors_after_request(app.make_response(f(*args, **kwargs)))
  File "D:\Apis\Flaskprojects\SaccoPaymentGateway\venv\lib\site-packages\flask\app.py", line 1820, in handle_user_exception
    reraise(exc_type, exc_value, tb)
  File "D:\Apis\Flaskprojects\SaccoPaymentGateway\venv\lib\site-packages\flask\app.py", line 1949, in full_dispatch_request
    rv = self.dispatch_request()
  File "D:\Apis\Flaskprojects\SaccoPaymentGateway\venv\lib\site-packages\flask\app.py", line 1935, in dispatch_request
    return self.view_functions[rule.endpoint](**req.view_args)
  File "D:\Apis\Flaskprojects\SaccoPaymentGateway\venv\lib\site-packages\flask_httpauth.py", line 105, in decorated
    return f(*args, **kwargs)
  File "D:\Apis\Flaskprojects\SaccoPaymentGateway\gateway\api\routes.py", line 212, in loan_application
    with Logic as logic:
AttributeError: __exit__
2020-04-19 01:32:49,637 INFO: Saccostartup [in D:\Apis\Flaskprojects\SaccoPaymentGateway\gateway\__init__.py:61]
